<?xml version="1.0" encoding="utf-8"?>
<!-- This URDF was automatically created by SolidWorks to URDF Exporter! Originally created by Stephen Brawner (brawner@gmail.com) 
     Commit Version: 1.6.0-4-g7f85cfe  Build Version: 1.6.7995.38578
     For more information, please see http://wiki.ros.org/sw_urdf_exporter -->
<robot
  name="two_wheel_robot">
  <link
    name="base_link">
    <inertial>
      <origin
        xyz="0.0181995182140738 -3.2612801348364E-16 -0.00276660416271973"
        rpy="0 0 0" />
      <mass
        value="0.443722021822356" />
      <inertia
        ixx="0.000696660783343318"
        ixy="-4.10541788338937E-18"
        ixz="-1.73835831247213E-05"
        iyy="0.000483852662901766"
        iyz="-9.39165770832175E-20"
        izz="0.00110580849651397" />
    </inertial>
    <visual>
      <origin
        xyz="0 0 0"
        rpy="0 0 0" />
      <geometry>
        <mesh
          filename="package://two_wheel_robot/meshes/base_link.STL" />
      </geometry>
      <material
        name="white">
        <color
          rgba="255 255 255 1" />
      </material>
    </visual>
    <collision>
      <origin
        xyz="0 0 0"
        rpy="0 0 0" />
      <geometry>
        <mesh
          filename="package://two_wheel_robot/meshes/base_link.STL" />
      </geometry>
    </collision>
  </link>
  <link
    name="left_wheel">
    <inertial>
      <origin
        xyz="-5.55111512312578E-16 -0.003175 5.96744875736022E-16"
        rpy="0 0 0" />
      <mass
        value="0.0200098005396681" />
      <inertia
        ixx="8.1981759107312E-06"
        ixy="-1.00227236420066E-21"
        ixz="-2.27167310991176E-21"
        iyy="1.62618776244189E-05"
        iyz="-1.73164708639823E-22"
        izz="8.1981759107312E-06" />
    </inertial>
    <visual>
      <origin
        xyz="0 0 0"
        rpy="0 0 0" />
      <geometry>
        <mesh
          filename="package://two_wheel_robot/meshes/left_wheel.STL" />
      </geometry>
      <material
        name="black">
        <color
          rgba="0 0 0 1" />
      </material>
    </visual>
    <collision>
      <origin
        xyz="0 0 0"
        rpy="0 0 0" />
      <geometry>
        <mesh
          filename="package://two_wheel_robot/meshes/left_wheel.STL" />
      </geometry>
    </collision>
  </link>
  <joint
    name="left_joint"
    type="continuous">
    <origin
      xyz="0 0.10055 -0.024525"
      rpy="0 0 0" />
    <parent
      link="base_link" />
    <child
      link="left_wheel" />
    <axis
      xyz="0 -1 0" />
  </joint>
  <link
    name="right_wheel">
    <inertial>
      <origin
        xyz="2.77555756156289E-17 0.00317500000000001 -7.63278329429795E-17"
        rpy="0 0 0" />
      <mass
        value="0.0200098005396681" />
      <inertia
        ixx="8.19817591073118E-06"
        ixy="1.19139779353411E-21"
        ixz="-5.16987882845644E-22"
        iyy="1.62618776244189E-05"
        iyz="2.65399463552688E-23"
        izz="8.19817591073119E-06" />
    </inertial>
    <visual>
      <origin
        xyz="0 0 0"
        rpy="0 0 0" />
      <geometry>
        <mesh
          filename="package://two_wheel_robot/meshes/right_wheel.STL" />
      </geometry>
      <material
        name="black">
        <color
          rgba="0 0 0 1" />
      </material>
    </visual>
    <collision>
      <origin
        xyz="0 0 0"
        rpy="0 0 0" />
      <geometry>
        <mesh
          filename="package://two_wheel_robot/meshes/right_wheel.STL" />
      </geometry>
    </collision>
  </link>
  <joint
    name="right_joint"
    type="continuous">
    <origin
      xyz="0 -0.10055 -0.024525"
      rpy="0 0 0" />
    <parent
      link="base_link" />
    <child
      link="right_wheel" />
    <axis
      xyz="0 -1 0" />
  </joint>
</robot>
